<robot name="PCR Workcell" >

  <!-- Materials -->

  <material name="green">
    <color rgba="0.0 0.8 0.0 1.0"/>
  </material>

  <material name="grey">
    <color rgba="0.2 0.2 0.2 1.0"/>
  </material>

  <material name="orange">
    <color rgba="1.0 0.423529411765 0.0392156862745 1.0"/>
  </material>
  
  <material name="brown">
    <color rgba="0.870588235294 0.811764705882 0.764705882353 1.0"/>
  </material>

  <material name="white">
    <color rgba="1 1 1 1"/>
  </material>

  <material name="black">
    <color rgba="0.2 0.2 0.2 1"/>
  </material>

  <material name="blue">
    <color rgba="0 0 0.8 1"/>
  </material>

  <material name="red">
    <color rgba="0.8 0.2 0.2 1"/>
  </material>

  <material name="pink">
    <color rgba="0.6 0.4 0.6 1"/>
  </material>

  <material name="dark_grey">
    <color rgba="0.4 0.4 0.4 1"/>
  </material>

  <material name="light_grey">
    <color rgba="0.9 0.9 0.9 1"/>
  </material>

  <material name="dark_blue">
    <color rgba="0.011764705882352941 0.027450980392156862 0.29215686274509803 1.0"/>
  </material>

  <material name="light_blue">
    <color rgba="0 0.5 0.8 1.0"/>
  </material>

  <material name="darkbluegrey" >
    <color rgba="0.12156862745098039 0.23137254901960785 0.30196078431372547 1.0" />
  </material>
  
  <material name="darkbluegreen" >
    <color rgba="0.0 0.2 0.23 1.0" />
  </material>

  <material name="aluminum">
    <color rgba="0.6 0.6 0.6 1"/>
  </material>
  

  <!-- Links -->
  <!-- PF400 -->
  <link name="rail_base">
    <visual>
      <origin xyz="0 0 0" rpy="0 0 1.5708"/>
      <geometry>
        <mesh filename="package://pf400_description/meshes/rail_base.STL" scale="1 1 1"/>
      </geometry>
      <material name="white"/>
    </visual>
    <collision>
      <geometry>
        <mesh filename="package://pf400_description/meshes/rail_base.STL" scale="1 1 1"/>
      </geometry>
      <origin xyz="0 0 0" rpy="0 0 1.5708"/>
    </collision>
  </link>

  <link name="rail">
    <visual>
      <origin xyz="0 0 0" rpy="1.5708 0 1.5708"/>
      <geometry>
        <mesh filename="package://pf400_description/meshes/rail.STL" scale="1 1 1"/>
      </geometry>
      <material name="white"/>
    </visual>
      <collision>
      <geometry>
        <mesh filename="package://pf400_description/meshes/rail.STL" scale="1 1 1"/>
      </geometry>
      <origin xyz="0 0 0" rpy="1.5708 0 1.5708"/>
    </collision>
  </link>

  <link name="z_column">
    <visual>
      <origin xyz="0 0 0.074" rpy="0 0 0"/>
      <geometry>
        <mesh filename="package://pf400_description/meshes/PF400_Z_Column.STL" scale="0.001 0.001 0.00132"/>
      </geometry>
      <material name="white"/>
    </visual>
      <collision>
      <geometry>
        <mesh filename="package://pf400_description/meshes/PF400_Z_Column.STL" scale="0.001 0.001 0.00132"/>
      </geometry>
      <origin xyz="0 0 0.074" rpy="0 0 0"/>
    </collision>
  </link>

  <link name="z_carriage">
    <visual>
      <origin xyz="0 0 0.074" rpy="0 0 0"/>
      <geometry>
        <mesh filename="package://pf400_description/meshes/PF400_Z_Carriage.STL" scale="0.001 0.001 0.001"/>
      </geometry>
      <material name="white"/>
    </visual>
      <collision>
      <geometry>
        <mesh filename="package://pf400_description/meshes/PF400_Z_Carriage.STL" scale="0.001 0.001 0.001"/>
      </geometry>
      <origin xyz="0 0 0.074" rpy="0 0 0"/>
    </collision>
  </link>

  <link name="inner_link">
    <visual>
      <origin xyz="0 0 0.074" rpy="0 0 0"/>
      <geometry>
        <mesh filename="package://pf400_description/meshes/PF400_Inner_Link.STL" scale="0.001 0.001 0.001"/>
      </geometry>
      <material name="white"/>
    </visual>
      <collision>
      <geometry>
        <mesh filename="package://pf400_description/meshes/PF400_Inner_Link.STL" scale="0.001 0.001 0.001"/>
      </geometry>
      <origin xyz="0 0 0.074" rpy="0 0 0"/>
    </collision>
  </link>

  <link name="outer_link">
    <visual>
      <origin xyz="0 0 0.074" rpy="0 0 0"/>
      <geometry>
        <mesh filename="package://pf400_description/meshes/PF400_Outer_Link.STL" scale="0.001 0.001 0.001"/>
      </geometry>
      <material name="white"/>
    </visual>
      <collision>
      <geometry>
        <mesh filename="package://pf400_description/meshes/PF400_Outer_Link.STL" scale="0.001 0.001 0.001"/>
      </geometry>
      <origin xyz="0 0 0.074" rpy="0 0 0"/>
    </collision>
  </link>

  <link name="hand">
    <visual>
      <origin xyz="0 0 0.074" rpy="0 0 0"/>
      <geometry>
        <mesh filename="package://pf400_description/meshes/PF400_Hand.STL" scale="0.001 0.001 0.001"/>
      </geometry>
      <material name="white"/>
    </visual>
      <collision>
      <geometry>
        <mesh filename="package://pf400_description/meshes/PF400_Hand.STL" scale="0.001 0.001 0.001"/>
      </geometry>
      <origin xyz="0 0 0.074" rpy="0 0 0"/>
    </collision>
  </link>

  <link name="left_finger">
    <visual>
      <origin xyz="-0.02 -0.053 0.040" rpy="0 0 0"/>
      <geometry>
        <mesh filename="package://pf400_description/meshes/pf400_left_finger.STL" scale="0.001 0.001 0.001"/>
      </geometry>
      <material name="aluminum"/>
    </visual>
      <collision>
      <geometry>
        <mesh filename="package://pf400_description/meshes/pf400_left_finger.STL" scale="0.001 0.001 0.001"/>
      </geometry>
      <origin xyz="-0.02 -0.053 0.040" rpy="0 0 0"/>
    </collision>
  </link>

  <link name="right_finger">
    <visual>
      <origin xyz="-0.021 -0.028 0.092" rpy="-1.5708 0 0"/>
      <geometry>
        <mesh filename="package://pf400_description/meshes/pf400_right_finger.STL" scale="0.001 0.001 0.001"/>
      </geometry>
      <material name="aluminum"/>
    </visual>
    <collision>
      <geometry>
        <mesh filename="package://pf400_description/meshes/pf400_right_finger.STL" scale="0.001 0.001 0.001"/>
      </geometry>
      <origin xyz="-0.021 -0.028 0.092" rpy="-1.5708 0 0"/>
    </collision>
  </link>


  <!-- Peeler -->
  <link name="peeler_base">
    <visual>
      <origin xyz="0 0 0" rpy="1.5708 0 0"/>
      <geometry>
        <mesh filename="package://azenta_description/meshes/peeler_base.STL" scale="0.001 0.001 0.001"/>
      </geometry>
      <material name="light_blue"/>
    </visual>
    <collision>
      <geometry>
        <mesh filename="package://azenta_description/meshes/peeler_base.STL" scale="0.001 0.001 0.001"/>
      </geometry>
      <origin xyz="0 0 0" rpy="1.5708 0 0"/>
    </collision>
  </link>

  <link name="peeler_plate">
    <visual>
      <origin xyz="0 0 0" rpy="0 1.5708 0"/>
      <geometry>
        <mesh filename="package://azenta_description/meshes/peeler_plate.STL" scale="0.001 0.001 0.001"/>
      </geometry>
      <material name="white"/>
    </visual>
    <collision>
      <geometry>
        <mesh filename="package://azenta_description/meshes/peeler_plate.STL" scale="0.001 0.001 0.001"/>
      </geometry>
      <origin xyz="0 0 0" rpy="0 1.5708 0"/>
    </collision>
  </link>

  <!-- Sealer -->
  <link name="sealer_base">
    <visual>
      <origin xyz="0 0 0" rpy="1.5708 0 1.5708"/>
      <geometry>
        <mesh filename="package://azenta_description/meshes/sealer_base.STL" scale="0.001 0.001 0.001"/>
      </geometry>
      <material name="pink"/>
    </visual>
    <collision>
      <geometry>
        <mesh filename="package://azenta_description/meshes/sealer_base.STL" scale="0.001 0.001 0.001"/>
      </geometry>
      <origin xyz="0 0 0" rpy="1.5708 0 1.5708"/>
    </collision>
  </link>

  <link name="sealer_plate">
    <visual>
      <origin xyz="0 0 0" rpy="0 1.5708 0"/>
      <geometry>
        <mesh filename="package://azenta_description/meshes/sealer_plate.STL" scale="0.001 0.001 0.001"/>
      </geometry>
      <material name="aluminum"/>
    </visual>
    <collision>
      <geometry>
        <mesh filename="package://azenta_description/meshes/sealer_plate.STL" scale="0.001 0.001 0.001"/>
      </geometry>
      <origin xyz="0 0 0" rpy="0 1.5708 0"/>
    </collision>
  </link>
  <!-- OT2 -->

  <link name="OT2_alpha">
    <visual>
      <origin xyz="0.36 0.94 1.042" rpy="0 0 0"/>
      <geometry>
        <mesh filename="package://ot2_description/meshes/OT2_base.stl" scale="1 1 1"/>
      </geometry>
      <material name="aluminum"/>
    </visual>
    <collision>
      <geometry>
        <mesh filename="package://ot2_description/meshes/OT2_base.stl" scale="1 1 1"/>
      </geometry>
      <origin xyz="0.36 0.94 1.042" rpy="0 0 0"/>
    </collision>
  </link>

  <link name="OT2_pipette_rail_alpha">
    <visual>
      <origin xyz="0.36 1.15 1.042" rpy="0 0 0"/>
      <geometry>
        <mesh filename="package://ot2_description/meshes/OT2_rail.stl" scale="1 1 1"/>
      </geometry>
      <material name="aluminum"/>
    </visual>
    <collision>
      <geometry>
        <mesh filename="package://ot2_description/meshes/OT2_rail.stl" scale="1 1 1"/>
      </geometry>
      <origin xyz="0.36 1.15 1.042" rpy="0 0 0"/>
    </collision>
  </link>

  <link name="OT2_pipette_base_alpha">
    <visual>
      <origin xyz="0.51 1.15 1.042" rpy="0 0 0"/>
      <geometry>
        <mesh filename="package://ot2_description/meshes/OT2_pipette_base.STL" scale="1 1 1"/>
      </geometry>
      <material name="aluminum"/>
    </visual>
    <collision>
      <geometry>
        <mesh filename="package://ot2_description/meshes/OT2_pipette_base.STL" scale="1 1 1"/>
      </geometry>
      <origin xyz="0.51 1.15 1.042" rpy="0 0 0"/>
    </collision>
  </link>

  <link name="OT2_single_pipette_alpha">
    <visual>
      <origin xyz="0.79 0.76 1.27" rpy="1.5708 0 1.5708"/>
      <geometry>
        <mesh filename="package://ot2_description/meshes/pipette.STL" scale="0.001 0.001 0.001"/>
      </geometry>
      <material name="black"/>
    </visual>
    <collision>
      <geometry>
        <mesh filename="package://ot2_description/meshes/pipette.STL" scale="0.001 0.001 0.001"/>
      </geometry>
      <origin xyz="0.79 0.76 1.27" rpy="1.5708 0 1.5708"/>
    </collision>
  </link>

  <link name="OT2_8_channel_pipette_alpha">
    <visual>
      <origin xyz="0.51 1.15 1.042" rpy="0 0 0"/>
      <geometry>
        <mesh filename="package://ot2_description/meshes/OT2_8ch_pipette.stl" scale="1 1 1"/>
      </geometry>
      <material name="black"/>
    </visual>
    <collision>
      <geometry>
        <mesh filename="package://ot2_description/meshes/OT2_8ch_pipette.stl" scale="1 1 1"/>
      </geometry>
      <origin xyz="0.51 1.15 1.042" rpy="0 0 0"/>
    </collision>
  </link>

  <link name="OT2_betha">
    <visual>
      <origin xyz="0.36 0.94 1.042" rpy="0 0 0"/>
      <geometry>
        <mesh filename="package://ot2_description/meshes/OT2_base.stl" scale="1 1 1"/>
      </geometry>
      <material name="aluminum"/>
    </visual>
    <collision>
      <geometry>
        <mesh filename="package://ot2_description/meshes/OT2_base.stl" scale="1 1 1"/>
      </geometry>
      <origin xyz="0.36 0.94 1.042" rpy="0 0 0"/>
    </collision>
  </link>

  <link name="OT2_pipette_rail_betha">
    <visual>
      <origin xyz="0.36 1.15 1.042" rpy="0 0 0"/>
      <geometry>
        <mesh filename="package://ot2_description/meshes/OT2_rail.stl" scale="1 1 1"/>
      </geometry>
      <material name="aluminum"/>
    </visual>
    <collision>
      <geometry>
        <mesh filename="package://ot2_description/meshes/OT2_rail.stl" scale="1 1 1"/>
      </geometry>
      <origin xyz="0.36 1.15 1.042" rpy="0 0 0"/>
    </collision>
  </link>

  <link name="OT2_pipette_base_betha">
    <visual>
      <origin xyz="0.51 1.15 1.042" rpy="0 0 0"/>
      <geometry>
        <mesh filename="package://ot2_description/meshes/OT2_pipette_base.STL" scale="1 1 1"/>
      </geometry>
      <material name="aluminum"/>
    </visual>
    <collision>
      <geometry>
        <mesh filename="package://ot2_description/meshes/OT2_pipette_base.STL" scale="1 1 1"/>
      </geometry>
      <origin xyz="0.51 1.15 1.042" rpy="0 0 0"/>
    </collision>
  </link>

  <link name="OT2_single_pipette_betha">
    <visual>
      <origin xyz="0.79 0.76 1.27" rpy="1.5708 0 1.5708"/>
      <geometry>
        <mesh filename="package://ot2_description/meshes/pipette.STL" scale="0.001 0.001 0.001"/>
      </geometry>
      <material name="black"/>
    </visual>
    <collision>
      <geometry>
        <mesh filename="package://ot2_description/meshes/pipette.STL" scale="0.001 0.001 0.001"/>
      </geometry>
      <origin xyz="0.79 0.76 1.27" rpy="1.5708 0 1.5708"/>
    </collision>
  </link>

  <link name="OT2_8_channel_pipette_betha">
    <visual>
      <origin xyz="0.51 1.15 1.042" rpy="0 0 0"/>
      <geometry>
        <mesh filename="package://ot2_description/meshes/OT2_8ch_pipette.stl" scale="1 1 1"/>
      </geometry>
      <material name="black"/>
    </visual>
    <collision>
      <geometry>
        <mesh filename="package://ot2_description/meshes/OT2_8ch_pipette.stl" scale="1 1 1"/>
      </geometry>
      <origin xyz="0.51 1.15 1.042" rpy="0 0 0"/>
    </collision>
  </link>

  <link name="OT2_gamma">
    <visual>
      <origin xyz="0.36 0.94 1.042" rpy="0 0 0"/>
      <geometry>
        <mesh filename="package://ot2_description/meshes/OT2_base.stl" scale="1 1 1"/>
      </geometry>
      <material name="aluminum"/>
    </visual>
    <collision>
      <geometry>
        <mesh filename="package://ot2_description/meshes/OT2_base.stl" scale="1 1 1"/>
      </geometry>
      <origin xyz="0.36 0.94 1.042" rpy="0 0 0"/>
    </collision>
  </link>

  <link name="OT2_pipette_rail_gamma">
    <visual>
      <origin xyz="0.36 1.15 1.042" rpy="0 0 0"/>
      <geometry>
        <mesh filename="package://ot2_description/meshes/OT2_rail.stl" scale="1 1 1"/>
      </geometry>
      <material name="aluminum"/>
    </visual>
    <collision>
      <geometry>
        <mesh filename="package://ot2_description/meshes/OT2_rail.stl" scale="1 1 1"/>
      </geometry>
      <origin xyz="0.36 1.15 1.042" rpy="0 0 0"/>
    </collision>
  </link>

  <link name="OT2_pipette_base_gamma">
    <visual>
      <origin xyz="0.51 1.15 1.042" rpy="0 0 0"/>
      <geometry>
        <mesh filename="package://ot2_description/meshes/OT2_pipette_base.STL" scale="1 1 1"/>
      </geometry>
      <material name="aluminum"/>
    </visual>
    <collision>
      <geometry>
        <mesh filename="package://ot2_description/meshes/OT2_pipette_base.STL" scale="1 1 1"/>
      </geometry>
      <origin xyz="0.51 1.15 1.042" rpy="0 0 0"/>
    </collision>
  </link>

  <link name="OT2_single_pipette_gamma">
    <visual>
      <origin xyz="0.79 0.76 1.27" rpy="1.5708 0 1.5708"/>
      <geometry>
        <mesh filename="package://ot2_description/meshes/pipette.STL" scale="0.001 0.001 0.001"/>
      </geometry>
      <material name="black"/>
    </visual>
    <collision>
      <geometry>
        <mesh filename="package://ot2_description/meshes/pipette.STL" scale="0.001 0.001 0.001"/>
      </geometry>
      <origin xyz="0.79 0.76 1.27" rpy="1.5708 0 1.5708"/>
    </collision>
  </link>

  <link name="OT2_8_channel_pipette_gamma">
    <visual>
      <origin xyz="0.51 1.15 1.042" rpy="0 0 0"/>
      <geometry>
        <mesh filename="package://ot2_description/meshes/OT2_8ch_pipette.stl" scale="1 1 1"/>
      </geometry>
      <material name="black"/>
    </visual>
    <collision>
      <geometry>
        <mesh filename="package://ot2_description/meshes/OT2_8ch_pipette.stl" scale="1 1 1"/>
      </geometry>
      <origin xyz="0.51 1.15 1.042" rpy="0 0 0"/>
    </collision>
  </link>

  <!-- Biometra -->
  <link name="biometra_base">
    <visual>
      <origin xyz="0 0.5 1.042" rpy="1.5708 0 0"/>
      <geometry>
        <mesh filename="package://biometra_description/meshes/biometra_base.STL" scale="0.001 0.001 0.001"/>
      </geometry>
      <material name="light_grey"/>
    </visual>
    <collision>
      <geometry>
        <mesh filename="package://biometra_description/meshes/biometra_base.STL" scale="0.001 0.001 0.001"/>
      </geometry>
      <origin xyz="0 0.5 1.042" rpy="1.5708 0 0"/>
    </collision>
  </link>

  <link name="biometra_cap">
    <visual>
      <origin xyz="0 0 0" rpy="0 0 0"/>
      <geometry>
        <mesh filename="package://biometra_description/meshes/biometra_cap.STL" scale="0.001 0.001 0.001"/>
      </geometry>
      <material name="red"/>
    </visual>
    <collision>
      <geometry>
        <mesh filename="package://biometra_description/meshes/biometra_cap.STL" scale="0.001 0.001 0.001"/>
      </geometry>
      <origin xyz="0 0 0" rpy="0 0 0"/>
    </collision>
  </link>

  <link name="biometra_base2">
    <visual>
      <origin xyz="0 0.5 1.042" rpy="1.5708 0 0"/>
      <geometry>
        <mesh filename="package://biometra_description/meshes/biometra_base.STL" scale="0.001 0.001 0.001"/>
      </geometry>
      <material name="light_grey"/>
    </visual>
    <collision>
      <geometry>
        <mesh filename="package://biometra_description/meshes/biometra_base.STL" scale="0.001 0.001 0.001"/>
      </geometry>
      <origin xyz="0 0.5 1.042" rpy="1.5708 0 0"/>
    </collision>
  </link>

  <link name="biometra_cap2">
    <visual>
      <origin xyz="0 0 0" rpy="0 0 0"/>
      <geometry>
        <mesh filename="package://biometra_description/meshes/biometra_cap.STL" scale="0.001 0.001 0.001"/>
      </geometry>
      <material name="red"/>
    </visual>
    <collision>
      <geometry>
        <mesh filename="package://biometra_description/meshes/biometra_cap.STL" scale="0.001 0.001 0.001"/>
      </geometry>
      <origin xyz="0 0 0" rpy="0 0 0"/>
    </collision>
  </link>

  <!-- Hidex -->
  <link name="hidex_body">
    <visual>
      <origin xyz="0 0 0" rpy="0 0 0"/>
      <geometry>
        <mesh filename="package://hidex_description/meshes/hidex_body.STL" scale="0.001 0.001 0.001"/>
      </geometry>
      <material name="black"/>
    </visual>
    <collision>
      <geometry>
        <mesh filename="package://hidex_description/meshes/hidex_body.STL" scale="0.001 0.001 0.001"/>
      </geometry>
      <origin xyz="0 0 0" rpy="0 0 0"/>
    </collision>
  </link>

  <link name="hidex_plate">
    <visual>
      <origin xyz="0 0 0" rpy="0 0 0"/>
      <geometry>
        <mesh filename="package://hidex_description/meshes/hidex_plate.STL" scale="0.001 0.001 0.001"/>
      </geometry>
      <material name="aluminum"/>
    </visual>
    <collision>
      <geometry>
        <mesh filename="package://hidex_description/meshes/hidex_plate.STL" scale="0.001 0.001 0.001"/>
      </geometry>
      <origin xyz="0 0 0" rpy="0 0 0"/>
    </collision>
  </link> 
  
  <!-- Module Carts -->
  <link name="cart_1">
    <visual>
      <origin xyz="0 0 0" rpy="0 0 0"/>
      <geometry>
        <mesh filename="package://pcr_description/meshes/module_cart.stl" scale="1 1 1"/>
      </geometry>
      <material name="darkbluegreen"/>
    </visual>
    <collision>
      <geometry>
        <mesh filename="package://pcr_description/meshes/module_cart.stl" scale="1 1 1"/>
      </geometry>
      <origin xyz="0 0 0" rpy="0 0 0"/>
    </collision>
  </link>

  <link name="cart_2">
    <visual>
      <origin xyz="0 0 0" rpy="0 0 0"/>
      <geometry>
        <mesh filename="package://pcr_description/meshes/module_cart.stl" scale="1 1 1"/>
      </geometry>
      <material name="darkbluegreen"/>
    </visual>
    <collision>
      <geometry>
        <mesh filename="package://pcr_description/meshes/module_cart.stl" scale="1 1 1"/>
      </geometry>
      <origin xyz="0 0 0" rpy="0 0 0"/>
    </collision>
  </link>

  <link name="cart_3">
    <visual>
      <origin xyz="0 0 0" rpy="0 0 0"/>
      <geometry>
        <mesh filename="package://pcr_description/meshes/module_cart.stl" scale="1 1 1"/>
      </geometry>
      <material name="darkbluegreen"/>
    </visual>
    <collision>
      <geometry>
        <mesh filename="package://pcr_description/meshes/module_cart.stl" scale="1 1 1"/>
      </geometry>
      <origin xyz="0 0 0" rpy="0 0 0"/>
    </collision>
  </link>

  <link name="cart_4">
    <visual>
      <origin xyz="0 0 0" rpy="0 0 0"/>
      <geometry>
        <mesh filename="package://pcr_description/meshes/module_cart.stl" scale="1 1 1"/>
      </geometry>
      <material name="darkbluegreen"/>
    </visual>
    <collision>
      <geometry>
        <mesh filename="package://pcr_description/meshes/module_cart.stl" scale="1 1 1"/>
      </geometry>
      <origin xyz="0 0 0" rpy="0 0 0"/>
    </collision>
  </link>

  <link name="cart_5">
    <visual>
      <origin xyz="0 0 0" rpy="0 0 0"/>
      <geometry>
        <mesh filename="package://pcr_description/meshes/module_cart.stl" scale="1 1 1"/>
      </geometry>
      <material name="darkbluegreen"/>
    </visual>
    <collision>
      <geometry>
        <mesh filename="package://pcr_description/meshes/module_cart.stl" scale="1 1 1"/>
      </geometry>
      <origin xyz="0 0 0" rpy="0 0 0"/>
    </collision>
  </link>
  
  <link name="cart_6">
    <visual>
      <origin xyz="0 0 0" rpy="0 0 0"/>
      <geometry>
        <mesh filename="package://pcr_description/meshes/module_cart.stl" scale="1 1 1"/>
      </geometry>
      <material name="darkbluegreen"/>
    </visual>
    <collision>
      <geometry>
        <mesh filename="package://pcr_description/meshes/module_cart.stl" scale="1 1 1"/>
      </geometry>
      <origin xyz="0 0 0" rpy="0 0 0"/>
    </collision>
  </link>

  <link name="cart_7">
    <visual>
      <origin xyz="0 0 0" rpy="0 0 0"/>
      <geometry>
        <mesh filename="package://pcr_description/meshes/module_cart.stl" scale="1 1 1"/>
      </geometry>
      <material name="darkbluegreen"/>
    </visual>
    <collision>
      <geometry>
        <mesh filename="package://pcr_description/meshes/module_cart.stl" scale="1 1 1"/>
      </geometry>
      <origin xyz="0 0 0" rpy="0 0 0"/>
    </collision>
  </link>

  <link name="cart_8">
    <visual>
      <origin xyz="0 0 0" rpy="0 0 0"/>
      <geometry>
        <mesh filename="package://pcr_description/meshes/module_cart.stl" scale="1 1 1"/>
      </geometry>
      <material name="darkbluegreen"/>
    </visual>
    <collision>
      <geometry>
        <mesh filename="package://pcr_description/meshes/module_cart.stl" scale="1 1 1"/>
      </geometry>
      <origin xyz="0 0 0" rpy="0 0 0"/>
    </collision>
  </link>

  <link name="pf400_cart">
    <visual>
      <origin xyz="-1.592 0.2605 -0.0" rpy="1.5708 0 0"/>
      <geometry>
        <mesh filename="package://pcr_description/meshes/pf400_table.STL" scale="0.001 0.001 0.001"/>
      </geometry>
      <material name="darkbluegreen"/>
    </visual>
    <collision>
      <geometry>
        <mesh filename="package://pcr_description/meshes/pf400_table.STL" scale="0.001 0.001 0.001"/>
      </geometry>
      <origin xyz="-1.592 0.261 -0.0" rpy="1.5708 0 0"/>
    </collision>
  </link>

  <!-- Sciclops -->

  <link name="sciclops_base">
    <visual>
      <origin xyz="0 0 0" rpy="1.5708 0 0"/>
      <geometry>
        <mesh filename="package://sciclops_description/meshes/Sciclops_base.STL" scale="0.001 0.001 0.001"/>
      </geometry>
      <material name="black"/>
    </visual>
    <collision>
      <geometry>
        <mesh filename="package://sciclops_description/meshes/Sciclops_base.STL" scale="0.001 0.001 0.001"/>
      </geometry>
      <origin xyz="0 0 0" rpy="1.5708 0 0"/>
    </collision>
  </link>

  <link name="sciclops_link1">
    <visual>
      <origin xyz="0 0 0" rpy="0 0 0"/>
      <geometry>
        <mesh filename="package://sciclops_description/meshes/Sciclops_joint1.STL" scale="0.001 0.001 0.001"/>
      </geometry>
      <material name="white"/>
    </visual>
    <collision>
      <geometry>
        <mesh filename="package://sciclops_description/meshes/Sciclops_joint1.STL" scale="0.001 0.001 0.001"/>
      </geometry>
      <origin xyz="0 0 0" rpy="0 0 0"/>
    </collision>
  </link>

  <link name="sciclops_link2">
    <visual>
      <origin xyz="0 0 0" rpy="0 0 0"/>
      <geometry>
        <mesh filename="package://sciclops_description/meshes/Sciclops_joint2.STL" scale="0.001 0.001 0.001"/>
      </geometry>
      <material name="white"/>
    </visual>
    <collision>
      <geometry>
        <mesh filename="package://sciclops_description/meshes/Sciclops_joint2.STL" scale="0.001 0.001 0.001"/>
      </geometry>
      <origin xyz="0 0 0" rpy="0 0 0"/>
    </collision>
  </link>

  <link name="sciclops_link3">
    <visual>
      <origin xyz="0 0 0" rpy="0 0 0"/>
      <geometry>
        <mesh filename="package://sciclops_description/meshes/Sciclops_joint3.STL" scale="0.001 0.001 0.001"/>
      </geometry>
      <material name="white"/>
    </visual>
    <collision>
      <geometry>
        <mesh filename="package://sciclops_description/meshes/Sciclops_joint3.STL" scale="0.001 0.001 0.001"/>
      </geometry>
      <origin xyz="0 0 0" rpy="0 0 0"/>
    </collision>
  </link>

  <link name="sciclops_link4">
    <visual>
      <origin xyz="0 0 0" rpy="0 0 0"/>
      <geometry>
        <mesh filename="package://sciclops_description/meshes/Sciclops_joint4.STL" scale="0.001 0.001 0.001"/>
      </geometry>
      <material name="white"/>
    </visual>
    <collision>
      <geometry>
        <mesh filename="package://sciclops_description/meshes/Sciclops_joint4.STL" scale="0.001 0.001 0.001"/>
      </geometry>
      <origin xyz="0 0 0" rpy="0 0 0"/>
    </collision>
  </link>


  
  <!-- Wrokcell Setup -->

 
  <joint name="pf400_cart_to_cart_1" type="fixed">
    <parent link="pf400_cart"/>
    <child link="cart_1"/>
    <axis xyz="0 0 1"/>
    <origin xyz="1.0 0.91 0.005" rpy="0 0 0"/>
    <limit effort="1000.0" lower="0" upper="0" velocity="0.5"/>
  </joint>
  
  <joint name="pf400_cart_to_cart_2" type="fixed">
    <parent link="pf400_cart"/>
    <child link="cart_2"/>
    <axis xyz="0 0 1"/>
    <origin xyz="0.25 0.91 0.005" rpy="0 0 0"/>
    <limit effort="1000.0" lower="0" upper="0" velocity="0.5"/>
  </joint>

  <joint name="pf400_cart_to_cart_3" type="fixed">
    <parent link="pf400_cart"/>
    <child link="cart_3"/>
    <axis xyz="0 0 1"/>
    <origin xyz="-0.50 0.91  0.005" rpy="0 0 0"/>
    <limit effort="1000.0" lower="0" upper="0" velocity="0.5"/>
  </joint>

  <joint name="pf400_cart_to_cart_4" type="fixed">
    <parent link="pf400_cart"/>
    <child link="cart_4"/>
    <axis xyz="0 0 1"/>
    <origin xyz="-1.25 0.91  0.005" rpy="0 0 0"/>
    <limit effort="1000.0" lower="0" upper="0" velocity="0.5"/>
  </joint>

  <joint name="pf400_cart_to_cart_5" type="fixed">
    <parent link="pf400_cart"/>
    <child link="cart_5"/>
    <axis xyz="0 0 1"/>
    <origin xyz="1.00 -0.54 0.005" rpy="0 0 0"/>
    <limit effort="1000.0" lower="0" upper="0" velocity="0.5"/>
  </joint>

  <joint name="pf400_cart_to_cart_6" type="fixed">
    <parent link="pf400_cart"/>
    <child link="cart_6"/>
    <axis xyz="0 0 1"/>
    <origin xyz="0.25 -0.54 0.005" rpy="0 0 0"/>
    <limit effort="1000.0" lower="0" upper="0" velocity="0.5"/>
  </joint>

  <joint name="pf400_cart_to_cart_7" type="fixed">
    <parent link="pf400_cart"/>
    <child link="cart_7"/>
    <axis xyz="0 0 1"/>
    <origin xyz="-0.50 -0.54 0.005" rpy="0 0 0"/>
    <limit effort="1000.0" lower="0" upper="0" velocity="0.5"/>
  </joint>

  <joint name="pf400_cart_to_cart_8" type="fixed">
    <parent link="pf400_cart"/>
    <child link="cart_8"/>
    <axis xyz="0 0 1"/>
    <origin xyz="-1.25 -0.54 0.005" rpy="0 0 0"/>
    <limit effort="1000.0" lower="0" upper="0" velocity="0.5"/>
  </joint>

  <joint name="Sealer_Plate_Joint" type="prismatic">
    <parent link="sealer_base"/>
    <child link="sealer_plate"/>
    <axis xyz="0 0 1"/>
    <origin xyz="0.057 0.28 0.01" rpy="1.5708 0 0"/>
    <limit effort="1000.0" lower="0.0" upper="0.25" velocity="0.5"/>
  </joint>

  <joint name="Peeler_Plate_Joint" type="prismatic">
    <parent link="peeler_base"/>
    <child link="peeler_plate"/>
    <axis xyz="0 0 1"/>
    <origin xyz="0.25 -0.18 0.083" rpy="1.5708 0 0"/> 
    <limit effort="1000.0" lower="0.0" upper="0.3" velocity="0.5"/>
  </joint>

  <joint name="Biometra_Cap" type="revolute">
    <parent link="biometra_base"/>
    <child link="biometra_cap"/>
    <axis xyz="-1 0 0"/>
    <origin xyz="0 0.466 1.05" rpy="1.5708 0 0"/>
    <limit effort="1000.0" lower="0.0" upper="1.2" velocity="0.5"/>
  </joint>

  <joint name="Biometra_Cap2" type="revolute">
    <parent link="biometra_base2"/>
    <child link="biometra_cap2"/>
    <axis xyz="-1 0 0"/>
    <origin xyz="0 0.466 1.05" rpy="1.5708 0 0"/>
    <limit effort="1000.0" lower="0.0" upper="1.2" velocity="0.5"/>
  </joint>

  <joint name="Hidex_Plate_Joint" type="prismatic">
    <parent link="hidex_body"/>
    <child link="hidex_plate"/>
    <axis xyz="0 0 1"/>
    <origin xyz="0.055 -0.09 0.065" rpy="0 0 0"/> 
    <limit effort="1000.0" lower="0" upper="0.3" velocity="0.5"/>
  </joint>

  <joint name="OT2_1_Pipette_Joint1_alpha" type="prismatic">
    <parent link="OT2_alpha"/>
    <child link="OT2_pipette_rail_alpha"/>
    <axis xyz="0 -1 0"/>
    <origin xyz="0 0 0" rpy="0 0 0"/>
    <limit effort="1000.0" lower="0" upper="0.3" velocity="0.5"/>
  </joint>

  <joint name="OT2_1_Pipette_Joint2_alpha" type="prismatic">
    <parent link="OT2_pipette_rail_alpha"/>
    <child link="OT2_pipette_base_alpha"/>
    <axis xyz="-1 0 0"/>
    <origin xyz="0 0 0" rpy="0 0 0"/>
    <limit effort="1000.0" lower="0" upper="0.3" velocity="0.5"/>
  </joint>

  <joint name="OT2_1_Single_Pipette_alpha" type="prismatic">
    <parent link="OT2_pipette_base_alpha"/>
    <child link="OT2_single_pipette_alpha"/>
    <axis xyz="0 0 -1"/>
    <origin xyz="0 0 0" rpy="0 0 0"/>
    <limit effort="1000.0" lower="0" upper="0.18" velocity="0.5"/>
  </joint>

  <joint name="OT2_1_8_Channel_Pipette_alpha" type="prismatic">
    <parent link="OT2_pipette_base_alpha"/>
    <child link="OT2_8_channel_pipette_alpha"/>
    <axis xyz="0 0 -1"/>
    <origin xyz="0 0 0" rpy="0 0 0"/>
    <limit effort="1000.0" lower="0" upper="0.18" velocity="0.5"/>
  </joint>

  <joint name="OT2_1_Pipette_Joint1_betha" type="prismatic">
    <parent link="OT2_betha"/>
    <child link="OT2_pipette_rail_betha"/>
    <axis xyz="0 -1 0"/>
    <origin xyz="0 0 0" rpy="0 0 0"/>
    <limit effort="1000.0" lower="0" upper="0.3" velocity="0.5"/>
  </joint>

  <joint name="OT2_1_Pipette_Joint2_betha" type="prismatic">
    <parent link="OT2_pipette_rail_betha"/>
    <child link="OT2_pipette_base_betha"/>
    <axis xyz="-1 0 0"/>
    <origin xyz="0 0 0" rpy="0 0 0"/>
    <limit effort="1000.0" lower="0" upper="0.3" velocity="0.5"/>
  </joint>

  <joint name="OT2_1_Single_Pipette_betha" type="prismatic">
    <parent link="OT2_pipette_base_betha"/>
    <child link="OT2_single_pipette_betha"/>
    <axis xyz="0 0 -1"/>
    <origin xyz="0 0 0" rpy="0 0 0"/>
    <limit effort="1000.0" lower="0" upper="0.18" velocity="0.5"/>
  </joint>

  <joint name="OT2_1_8_Channel_Pipette_betha" type="prismatic">
    <parent link="OT2_pipette_base_betha"/>
    <child link="OT2_8_channel_pipette_betha"/>
    <axis xyz="0 0 -1"/>
    <origin xyz="0 0 0" rpy="0 0 0"/>
    <limit effort="1000.0" lower="0" upper="0.18" velocity="0.5"/>
  </joint>

  <joint name="OT2_1_Pipette_Joint1_gamma" type="prismatic">
    <parent link="OT2_gamma"/>
    <child link="OT2_pipette_rail_gamma"/>
    <axis xyz="0 -1 0"/>
    <origin xyz="0 0 0" rpy="0 0 0"/>
    <limit effort="1000.0" lower="0" upper="0.3" velocity="0.5"/>
  </joint>

  <joint name="OT2_1_Pipette_Joint2_gamma" type="prismatic">
    <parent link="OT2_pipette_rail_gamma"/>
    <child link="OT2_pipette_base_gamma"/>
    <axis xyz="-1 0 0"/>
    <origin xyz="0 0 0" rpy="0 0 0"/>
    <limit effort="1000.0" lower="0" upper="0.3" velocity="0.5"/>
  </joint>

  <joint name="OT2_1_Single_Pipette_gamma" type="prismatic">
    <parent link="OT2_pipette_base_gamma"/>
    <child link="OT2_single_pipette_gamma"/>
    <axis xyz="0 0 -1"/>
    <origin xyz="0 0 0" rpy="0 0 0"/>
    <limit effort="1000.0" lower="0" upper="0.18" velocity="0.5"/>
  </joint>

  <joint name="OT2_1_8_Channel_Pipette_gamma" type="prismatic">
    <parent link="OT2_pipette_base_gamma"/>
    <child link="OT2_8_channel_pipette_gamma"/>
    <axis xyz="0 0 -1"/>
    <origin xyz="0 0 0" rpy="0 0 0"/>
    <limit effort="1000.0" lower="0" upper="0.18" velocity="0.5"/>
  </joint>

  <joint name="J1" type="prismatic">
    <parent link="z_column"/>
    <child link="z_carriage"/>
    <axis xyz="0 0 1"/>
    <origin xyz="0.03005 -0.0198 0.17535" rpy="0 0 0"/>
    <limit effort="1000.0" lower="0.002" upper="1.160" velocity="0.5"/> 
  </joint>

  <joint name="J2" type="revolute">
    <parent link="z_carriage"/>
    <child link="inner_link"/>
    <axis xyz="0 0 1"/>
    <origin xyz="0.173001 0.020 0.0235" rpy="0 0 0"/>
    <limit effort="1000.0" lower="-1.62316" upper="1.62316" velocity="0.5"/>
  </joint>

  <joint name="J3" type="revolute">
    <parent link="inner_link"/>
    <child link="outer_link"/>
    <axis xyz="0 0 1"/>
    <origin xyz="0.302 0 -0.072285" rpy="0 0 0"/>
    <limit effort="1000.0" lower="0.175" upper="6.1" velocity="0.5"/>
  </joint>

  <joint name="J4" type="revolute">
    <parent link="outer_link"/>
    <child link="hand"/>
    <axis xyz="0 0 1"/>
    <origin xyz="0.289 0 -0.032942" rpy="0 0 0"/>
    <limit effort="1000.0" lower="-16.7552" upper="16.7552" velocity="0.5"/>
  </joint>

  <joint name="J5" type="prismatic">
    <parent link="hand"/>
    <child link="left_finger"/>
    <axis xyz="0 1 0"/>
    <origin xyz="0.078573 0 -0.04269" rpy="0 0 0"/>
    <limit effort="1000.0" lower="0.04" upper="0.0675" velocity="0.5"/>
  </joint>

  <joint name="J5_mirror" type="prismatic">
    <parent link="hand"/>
    <child link="right_finger"/>
    <axis xyz="0 -1 0"/>
    <origin xyz="0.078573 0 -0.04269" rpy="0 0 0"/>
    <limit effort="1000.0" lower="0.04" upper="0.0675" velocity="0.5"/>
    <mimic joint="J5" multiplier="1"/>
  </joint>

  <joint name="J6" type="prismatic">
    <parent link="rail_base"/>
    <child link="rail"/>
    <axis xyz="1 0 0"/>
    <origin xyz="0 0 0.032" rpy="0 0 0"/>
    <limit effort="1000.0" lower="-1" upper="1" velocity="0.5"/>
  </joint>

  <joint name="rail_link" type="fixed">
    <parent link="rail"/>
    <child link="z_column"/>
    <axis xyz="0 1 0"/>
    <origin xyz="-0.1005 0 0.0157" rpy="0 0 0"/>
    <limit effort="1000.0" lower="0" upper="0" velocity="0.5"/>
  </joint>


  <joint name="Sciclops_joint1" type="revolute">
    <parent link="sciclops_base"/>
    <child link="sciclops_link1"/>
    <axis xyz="0 1 0"/>
    <origin xyz="0 0 0" rpy="1.5708 0 0"/> 
    <limit effort="1000.0" lower="-3.1" upper="3.1" velocity="0.5"/>
  </joint>

  <joint name="Sciclops_joint2" type="prismatic">
    <parent link="sciclops_link1"/>
    <child link="sciclops_link2"/>
    <axis xyz="0 1 0"/>
    <origin xyz="0 0 0" rpy="0 0 0"/> 
    <limit effort="1000.0" lower="-0.45" upper="0" velocity="0.5"/>
  </joint>

  <joint name="Sciclops_joint3" type="prismatic">
    <parent link="sciclops_link2"/>
    <child link="sciclops_link3"/>
    <axis xyz="0 0 1"/>
    <origin xyz="0 0 0" rpy="0 0 0"/> 
    <limit effort="1000.0" lower="-0.1" upper="0" velocity="0.5"/>
  </joint>

  <joint name="Sciclops_joint4" type="revolute">
    <parent link="sciclops_link3"/>
    <child link="sciclops_link4"/>
    <axis xyz="0 1 0"/>
    <origin xyz="0 0 0" rpy="0 0 0"/> 
    <limit effort="1000.0" lower="-3.1" upper="3.1" velocity="0.5"/>
  </joint>    

  <joint name="pf400_module" type="fixed">
    <parent link="pf400_cart"/>
    <child link="rail_base"/>
    <axis xyz="0 0 0"/>
    <origin xyz="-0.14 -0.0198 0.83" rpy="0 0 0"/>
    <limit effort="1000.0" lower="0" upper="0" velocity="0.5"/>
  </joint>

  <joint name="Biometra_Base" type="fixed">
    <parent link="cart_2"/>
    <child link="biometra_base"/>
    <axis xyz="0 0 0"/>
    <origin xyz="0.2 -0.62 0.01" rpy="0 0 0"/>
    <limit effort="1000.0" lower="0" upper="0" velocity="0.5"/>
  </joint>

  <joint name="Biometra_Base2" type="fixed">
    <parent link="cart_2"/>
    <child link="biometra_base2"/>
    <axis xyz="0 0 0"/>
    <origin xyz="-0.1 -0.62 0.01" rpy="0 0 0"/>
    <limit effort="1000.0" lower="0" upper="0" velocity="0.5"/>
  </joint>

 <joint name="Sciclops_Base" type="fixed">
    <parent link="cart_5"/>
    <child link="sciclops_base"/>
    <axis xyz="0 0 0"/>
    <origin xyz="0 -0.04 1.05" rpy="0 0 5.1"/> 
    <limit effort="1000.0" lower="0" upper="0" velocity="0.5"/>
  </joint>
  
  <joint name="Peeler_Base" type="fixed">
    <parent link="cart_6"/>
    <child link="peeler_base"/>
    <axis xyz="0 0 0"/>
    <origin xyz="-0.13 0.15 1.052" rpy="0 0 0"/>
    <limit effort="1000.0" lower="0" upper="0" velocity="0.5"/>
  </joint>

  <joint name="Sealer_Base" type="fixed">
    <parent link="cart_6"/>
    <child link="sealer_base"/>
    <axis xyz="0 0 0"/>
    <origin xyz="0.27 -0.53 1.052" rpy="0 0 0"/> 
    <limit effort="1000.0" lower="0" upper="0" velocity="0.5"/>
  </joint>

  <joint name="Hidex_Base" type="fixed">
    <parent link="cart_3"/>
    <child link="hidex_body"/>
    <axis xyz="0 0 0"/>
    <origin xyz="0.2 -0.45 1.052" rpy="0 0 0"/> 
    <limit effort="1000.0" lower="0" upper="0" velocity="0.5"/>
  </joint>

  <joint name="OT2_alpha" type="fixed">
    <parent link="cart_8"/>
    <child link="OT2_alpha"/>
    <axis xyz="0 0 0"/>
    <origin xyz="0.825 0.47 0.01" rpy="0 0 3.1416"/>
    <limit effort="1000.0" lower="0" upper="0" velocity="0.5"/>
  </joint>

  <joint name="OT2_betha" type="fixed">
    <parent link="cart_7"/>
    <child link="OT2_betha"/>
    <axis xyz="0 0 0"/>
    <origin xyz="0.825 0.47 0.01" rpy="0 0 3.1416"/>
    <limit effort="1000.0" lower="0" upper="0" velocity="0.5"/>
  </joint>

  <joint name="OT2_gamma" type="fixed">
    <parent link="cart_4"/>
    <child link="OT2_gamma"/>
    <axis xyz="0 0 0"/>
    <origin xyz="-0.52 -0.85 0.01" rpy="0 0 0"/>
    <limit effort="1000.0" lower="0" upper="0" velocity="0.5"/>
  </joint>

</robot>
